Traceback (most recent call last):
  File "/opt/jupyterhub/lib/python3.10/site-packages/jupyter_cache/executors/utils.py", line 58, in single_nb_execution
    executenb(
  File "/opt/jupyterhub/lib/python3.10/site-packages/nbclient/client.py", line 1314, in execute
    return NotebookClient(nb=nb, resources=resources, km=km, **kwargs).execute()
  File "/opt/jupyterhub/lib/python3.10/site-packages/jupyter_core/utils/__init__.py", line 165, in wrapped
    return loop.run_until_complete(inner)
  File "/usr/lib/python3.10/asyncio/base_events.py", line 649, in run_until_complete
    return future.result()
  File "/opt/jupyterhub/lib/python3.10/site-packages/nbclient/client.py", line 709, in async_execute
    await self.async_execute_cell(
  File "/opt/jupyterhub/lib/python3.10/site-packages/nbclient/client.py", line 1062, in async_execute_cell
    await self._check_raise_for_error(cell, cell_index, exec_reply)
  File "/opt/jupyterhub/lib/python3.10/site-packages/nbclient/client.py", line 918, in _check_raise_for_error
    raise CellExecutionError.from_cell_and_msg(cell, exec_reply_content)
nbclient.exceptions.CellExecutionError: An error occurred while executing the following cell:
------------------
import epamodule as em  # import the package
------------------


[0;31m---------------------------------------------------------------------------[0m
[0;31mOSError[0m                                   Traceback (most recent call last)
Cell [0;32mIn[3], line 1[0m
[0;32m----> 1[0m [38;5;28;01mimport[39;00m [38;5;21;01mepamodule[39;00m [38;5;28;01mas[39;00m [38;5;21;01mem[39;00m  [38;5;66;03m# import the package[39;00m

File [0;32m~/ects-epanet/ects-epanet-notes/lessons/lesson03/epamodule.py:12[0m
[1;32m     10[0m _plat[38;5;241m=[39m platform[38;5;241m.[39msystem()
[1;32m     11[0m [38;5;28;01mif[39;00m _plat[38;5;241m==[39m[38;5;124m'[39m[38;5;124mLinux[39m[38;5;124m'[39m:
[0;32m---> 12[0m   _lib [38;5;241m=[39m [43mctypes[49m[38;5;241;43m.[39;49m[43mCDLL[49m[43m([49m[38;5;124;43m"[39;49m[38;5;124;43m./libepanet2.so[39;49m[38;5;124;43m"[39;49m[43m)[49m [38;5;66;03m# For My Raspberry Pi[39;00m
[1;32m     13[0m [38;5;66;03m##  _lib = ctypes.CDLL("./en2tools.so.1.5.0")[39;00m
[1;32m     14[0m [38;5;66;03m##  _lib = ctypes.CDLL("./epanet2toolkit.so")[39;00m
[1;32m     15[0m [38;5;28;01melif[39;00m _plat[38;5;241m==[39m[38;5;124m'[39m[38;5;124mWindows[39m[38;5;124m'[39m:

File [0;32m/usr/lib/python3.10/ctypes/__init__.py:374[0m, in [0;36mCDLL.__init__[0;34m(self, name, mode, handle, use_errno, use_last_error, winmode)[0m
[1;32m    371[0m [38;5;28mself[39m[38;5;241m.[39m_FuncPtr [38;5;241m=[39m _FuncPtr
[1;32m    373[0m [38;5;28;01mif[39;00m handle [38;5;129;01mis[39;00m [38;5;28;01mNone[39;00m:
[0;32m--> 374[0m     [38;5;28mself[39m[38;5;241m.[39m_handle [38;5;241m=[39m [43m_dlopen[49m[43m([49m[38;5;28;43mself[39;49m[38;5;241;43m.[39;49m[43m_name[49m[43m,[49m[43m [49m[43mmode[49m[43m)[49m
[1;32m    375[0m [38;5;28;01melse[39;00m:
[1;32m    376[0m     [38;5;28mself[39m[38;5;241m.[39m_handle [38;5;241m=[39m handle

[0;31mOSError[0m: ./libepanet2.so: cannot open shared object file: No such file or directory

