Traceback (most recent call last):
  File "/opt/jupyterhub/lib/python3.8/site-packages/jupyter_cache/executors/utils.py", line 51, in single_nb_execution
    executenb(
  File "/opt/jupyterhub/lib/python3.8/site-packages/nbclient/client.py", line 1087, in execute
    return NotebookClient(nb=nb, resources=resources, km=km, **kwargs).execute()
  File "/opt/jupyterhub/lib/python3.8/site-packages/nbclient/util.py", line 74, in wrapped
    return just_run(coro(*args, **kwargs))
  File "/opt/jupyterhub/lib/python3.8/site-packages/nbclient/util.py", line 53, in just_run
    return loop.run_until_complete(coro)
  File "/usr/lib/python3.8/asyncio/base_events.py", line 616, in run_until_complete
    return future.result()
  File "/opt/jupyterhub/lib/python3.8/site-packages/nbclient/client.py", line 540, in async_execute
    await self.async_execute_cell(
  File "/opt/jupyterhub/lib/python3.8/site-packages/nbclient/client.py", line 832, in async_execute_cell
    self._check_raise_for_error(cell, exec_reply)
  File "/opt/jupyterhub/lib/python3.8/site-packages/nbclient/client.py", line 740, in _check_raise_for_error
    raise CellExecutionError.from_cell_and_msg(cell, exec_reply['content'])
nbclient.exceptions.CellExecutionError: An error occurred while executing the following cell:
------------------
import epamodule as em
------------------

[0;31m---------------------------------------------------------------------------[0m
[0;31mOSError[0m                                   Traceback (most recent call last)
[0;32m<ipython-input-4-a8199a9dd0bf>[0m in [0;36m<module>[0;34m[0m
[0;32m----> 1[0;31m [0;32mimport[0m [0mepamodule[0m [0;32mas[0m [0mem[0m[0;34m[0m[0;34m[0m[0m
[0m
[0;32m~/ects-epanet/ects-epanet-notes/lessons/lesson03/epamodule.py[0m in [0;36m<module>[0;34m[0m
[1;32m     10[0m [0m_plat[0m[0;34m=[0m [0mplatform[0m[0;34m.[0m[0msystem[0m[0;34m([0m[0;34m)[0m[0;34m[0m[0;34m[0m[0m
[1;32m     11[0m [0;32mif[0m [0m_plat[0m[0;34m==[0m[0;34m'Linux'[0m[0;34m:[0m[0;34m[0m[0;34m[0m[0m
[0;32m---> 12[0;31m   [0m_lib[0m [0;34m=[0m [0mctypes[0m[0;34m.[0m[0mCDLL[0m[0;34m([0m[0;34m"./libepanet2.so"[0m[0;34m)[0m[0;34m[0m[0;34m[0m[0m
[0m[1;32m     13[0m [0;31m##  _lib = ctypes.CDLL("./en2tools.so.1.5.0")[0m[0;34m[0m[0;34m[0m[0;34m[0m[0m
[1;32m     14[0m [0;31m##  _lib = ctypes.CDLL("./epanet2toolkit.so")[0m[0;34m[0m[0;34m[0m[0;34m[0m[0m

[0;32m/usr/lib/python3.8/ctypes/__init__.py[0m in [0;36m__init__[0;34m(self, name, mode, handle, use_errno, use_last_error, winmode)[0m
[1;32m    371[0m [0;34m[0m[0m
[1;32m    372[0m         [0;32mif[0m [0mhandle[0m [0;32mis[0m [0;32mNone[0m[0;34m:[0m[0;34m[0m[0;34m[0m[0m
[0;32m--> 373[0;31m             [0mself[0m[0;34m.[0m[0m_handle[0m [0;34m=[0m [0m_dlopen[0m[0;34m([0m[0mself[0m[0;34m.[0m[0m_name[0m[0;34m,[0m [0mmode[0m[0;34m)[0m[0;34m[0m[0;34m[0m[0m
[0m[1;32m    374[0m         [0;32melse[0m[0;34m:[0m[0;34m[0m[0;34m[0m[0m
[1;32m    375[0m             [0mself[0m[0;34m.[0m[0m_handle[0m [0;34m=[0m [0mhandle[0m[0;34m[0m[0;34m[0m[0m

[0;31mOSError[0m: ./libepanet2.so: cannot open shared object file: No such file or directory
OSError: ./libepanet2.so: cannot open shared object file: No such file or directory

